Loaded module: cuda/12.2
/zhome/4e/b/208805/.local/lib/python3.9/site-packages/keras/src/layers/layer.py:358: UserWarning: `build()` was called on layer 'patch_encoder', however the layer does not have a `build()` method implemented and it looks like it has unbuilt state. This will cause the layer to be marked as built, despite not being actually built, which may cause failures down the line. Make sure to implement a proper `build()` method.
  warnings.warn(
  0%|          | 0/500 [00:00<?, ?it/s]  3%|▎         | 14/500 [00:00<00:03, 139.95it/s]  6%|▌         | 29/500 [00:00<00:03, 143.09it/s]  9%|▉         | 44/500 [00:00<00:03, 145.08it/s] 12%|█▏        | 59/500 [00:00<00:03, 146.90it/s] 15%|█▍        | 74/500 [00:00<00:02, 146.90it/s] 18%|█▊        | 89/500 [00:00<00:02, 146.43it/s] 21%|██        | 104/500 [00:00<00:02, 145.04it/s] 24%|██▍       | 119/500 [00:00<00:02, 145.60it/s] 27%|██▋       | 134/500 [00:00<00:02, 145.62it/s] 30%|██▉       | 149/500 [00:01<00:02, 145.14it/s] 33%|███▎      | 164/500 [00:01<00:02, 144.80it/s] 36%|███▌      | 179/500 [00:01<00:02, 144.15it/s] 39%|███▉      | 194/500 [00:01<00:02, 144.49it/s] 42%|████▏     | 209/500 [00:01<00:01, 145.86it/s] 45%|████▍     | 224/500 [00:01<00:01, 146.46it/s] 48%|████▊     | 239/500 [00:01<00:01, 146.62it/s] 51%|█████     | 254/500 [00:01<00:01, 146.65it/s] 54%|█████▍    | 269/500 [00:01<00:01, 145.67it/s] 57%|█████▋    | 284/500 [00:01<00:01, 144.98it/s] 60%|█████▉    | 299/500 [00:02<00:01, 145.67it/s] 63%|██████▎   | 314/500 [00:02<00:01, 145.27it/s] 66%|██████▌   | 329/500 [00:02<00:01, 145.74it/s] 69%|██████▉   | 344/500 [00:02<00:01, 145.39it/s] 72%|███████▏  | 359/500 [00:02<00:00, 144.63it/s] 75%|███████▍  | 374/500 [00:02<00:00, 145.15it/s] 78%|███████▊  | 389/500 [00:02<00:00, 144.37it/s] 81%|████████  | 404/500 [00:02<00:00, 144.11it/s] 84%|████████▍ | 419/500 [00:02<00:00, 144.09it/s] 87%|████████▋ | 434/500 [00:02<00:00, 143.79it/s] 90%|████████▉ | 449/500 [00:03<00:00, 142.87it/s] 93%|█████████▎| 464/500 [00:03<00:00, 143.65it/s] 96%|█████████▌| 480/500 [00:03<00:00, 145.52it/s] 99%|█████████▉| 495/500 [00:03<00:00, 146.04it/s]100%|██████████| 500/500 [00:03<00:00, 145.13it/s]
Traceback (most recent call last):
  File "/dtu/p1/johlau/LabelReliability_and_PathologyDetection_in_ChestXrays/ObjectDetection/get_object_preds.py", line 73, in <module>
    preds = model.predict(input_images)
  File "/zhome/4e/b/208805/.local/lib/python3.9/site-packages/keras/src/utils/traceback_utils.py", line 123, in error_handler
    raise e.with_traceback(filtered_tb) from None
  File "/zhome/4e/b/208805/.local/lib/python3.9/site-packages/keras/src/models/functional.py", line 274, in _adjust_input_rank
    raise ValueError(
ValueError: Invalid input shape for input Traced<ShapedArray(float32[1,500,224,224,3])>with<DynamicJaxprTrace(level=1/0)>. Expected shape (None, 224, 224, 3), but input has incompatible shape (1, 500, 224, 224, 3)
