Loaded module: cuda/12.2
/zhome/4e/b/208805/.local/lib/python3.9/site-packages/keras/src/layers/layer.py:358: UserWarning: `build()` was called on layer 'patch_encoder', however the layer does not have a `build()` method implemented and it looks like it has unbuilt state. This will cause the layer to be marked as built, despite not being actually built, which may cause failures down the line. Make sure to implement a proper `build()` method.
  warnings.warn(
Traceback (most recent call last):
  File "/zhome/4e/b/208805/.local/lib/python3.9/site-packages/pandas/core/indexes/base.py", line 3791, in get_loc
    return self._engine.get_loc(casted_key)
  File "index.pyx", line 152, in pandas._libs.index.IndexEngine.get_loc
  File "index.pyx", line 181, in pandas._libs.index.IndexEngine.get_loc
  File "pandas/_libs/hashtable_class_helper.pxi", line 7080, in pandas._libs.hashtable.PyObjectHashTable.get_item
  File "pandas/_libs/hashtable_class_helper.pxi", line 7088, in pandas._libs.hashtable.PyObjectHashTable.get_item
KeyError: 'ImagePaths'

The above exception was the direct cause of the following exception:

Traceback (most recent call last):
  File "/dtu/p1/johlau/LabelReliability_and_PathologyDetection_in_ChestXrays/ObjectDetection/get_object_preds.py", line 61, in <module>
    source_paths = train_df.iloc[:int(n/2)]["ImagePaths"]
  File "/zhome/4e/b/208805/.local/lib/python3.9/site-packages/pandas/core/frame.py", line 3893, in __getitem__
    indexer = self.columns.get_loc(key)
  File "/zhome/4e/b/208805/.local/lib/python3.9/site-packages/pandas/core/indexes/base.py", line 3798, in get_loc
    raise KeyError(key) from err
KeyError: 'ImagePaths'
